tests/smoke/.smoke/joined_preview.csv
ask_price_1,ask_size_1,bid_price_1,bid_size_1,ask_price_2,ask_size_2,bid_price_2,bid_size_2,ask_price_3,ask_size_3,bid_price_3,bid_size_3,ask_price_4,ask_size_4,bid_price_4,bid_size_4,ask_price_5,ask_size_5,bid_price_5,bid_size_5,ask_price_6,ask_size_6,bid_price_6,bid_size_6,ask_price_7,ask_size_7,bid_price_7,bid_size_7,ask_price_8,ask_size_8,bid_price_8,bid_size_8,ask_price_9,ask_size_9,bid_price_9,bid_size_9,ask_price_10,ask_size_10,bid_price_10,bid_size_10,time,delta_t,type,order_id,size,price,direction
5859400,200,5853300,18,5859800,200,5853000,150,5861000,200,5851000,5,5868900,300,5850100,89,5869500,50,5849700,5,5870000,100,5849300,300,5871000,10,5846500,300,5873900,100,5845300,300,5876500,1160,5843800,200,5879000,500,5842700,300,34200.004241176,,1,16113575,18,5853300,1
5859400,200,5853300,18,5859800,200,5853200,18,5861000,200,5853000,150,5868900,300,5851000,5,5869500,50,5850100,89,5870000,100,5849700,5,5871000,10,5849300,300,5873900,100,5846500,300,5876500,1160,5845300,300,5879000,500,5843800,200,34200.00426064,1.9464001525193453e-05,1,16113584,18,5853200,1
5859400,200,5853300,18,5859800,200,5853200,18,5861000,200,5853100,18,5868900,300,5853000,150,5869500,50,5851000,5,5870000,100,5850100,89,5871000,10,5849700,5,5873900,100,5849300,300,5876500,1160,5846500,300,5879000,500,5845300,300,34200.004447484,0.00018684400129131973,1,16113594,18,5853100,1
5859100,18,5853300,18,5859400,200,5853200,18,5859800,200,5853100,18,5861000,200,5853000,150,5868900,300,5851000,5,5869500,50,5850100,89,5870000,100,5849700,5,5871000,10,5849300,300,5873900,100,5846500,300,5876500,1160,5845300,300,34200.025551909,0.021104424995428417,1,16120456,18,5859100,-1
5859100,18,5853300,18,5859200,18,5853200,18,5859400,200,5853100,18,5859800,200,5853000,150,5861000,200,5851000,5,5868900,300,5850100,89,5869500,50,5849700,5,5870000,100,5849300,300,5871000,10,5846500,300,5873900,100,5845300,300,34200.025579546,2.763700467767194e-05,1,16120480,18,5859200,-1
5859100,18,5853300,18,5859200,18,5853200,18,5859300,18,5853100,18,5859400,200,5853000,150,5859800,200,5851000,5,5861000,200,5850100,89,5868900,300,5849700,5,5869500,50,5849300,300,5870000,100,5846500,300,5871000,10,5845300,300,34200.025613151,3.360499977134168e-05,1,16120503,18,5859300,-1
5859100,18,5853300,18,5859200,18,5853200,18,5859300,18,5853100,18,5859400,200,5853000,150,5859800,200,5851000,5,5861000,200,5850100,89,5868900,300,5850000,100,5869500,50,5849700,5,5870000,100,5849300,300,5871000,10,5846500,300,34200.050241056,0.0246279049970326,1,16127688,100,5850000,1
5859100,18,5853300,18,5859200,18,5853200,18,5859300,118,5853100,18,5859400,200,5853000,150,5859800,200,5851000,5,5861000,200,5850100,89,5868900,300,5850000,100,5869500,50,5849700,5,5870000,100,5849300,300,5871000,10,5846500,300,34200.201517942,0.151276885997504,1,16166035,100,5859300,-1
